{
	"spawn": {
		"x": 0.5, "y": 3.0, "z": 0.5
	},
	"blocks": [
		{ "id": 1, "x": -2, "y": 0, "z": 1 },
		{ "id": 1, "x": -1, "y": 0, "z": 1 },
		{ "id": 1, "x": 0, "y": 0, "z": 1 },
		{ "id": 1, "x": 1, "y": 0, "z": 1 },
		{ "id": 1, "x": 2, "y": 0, "z": 1 },
		{ "id": 1, "x": -2, "y": 0, "z": 0 },
		{ "id": 1, "x": -1, "y": 0, "z": 0 },
		{ "id": 1, "x": 0, "y": 0, "z": 0 },
		{ "id": 1, "x": 1, "y": 0, "z": 0 },
		{ "id": 1, "x": 2, "y": 0, "z": 0 },
		{ "id": 1, "x": -2, "y": 0, "z": -1 },
		{ "id": 1, "x": -1, "y": 0, "z": -1 },
		{ "id": 1, "x": 0, "y": 0, "z": -1 },
		{ "id": 1, "x": 1, "y": 0, "z": -1 },
		{ "id": 1, "x": 2, "y": 0, "z": -1 },
		{ "id": 1, "x": -2, "y": 0, "z": -2 },
		{ "id": 1, "x": -1, "y": 0, "z": -2 },
		{ "id": 1, "x": 0, "y": 0, "z": -2 },
		{ "id": 1, "x": 1, "y": 0, "z": -2 },
		{ "id": 1, "x": 2, "y": 0, "z": -2 },
		{ "id": 1, "x": -2, "y": 0, "z": -3 },
		{ "id": 1, "x": -1, "y": 0, "z": -3 },
		{ "id": 1, "x": 0, "y": 0, "z": -3 },
		{ "id": 1, "x": 1, "y": 0, "z": -3 },
		{ "id": 1, "x": 2, "y": 0, "z": -3 },

		{ "id": 1, "x": -2, "y": 0, "z": -8 },
		{ "id": 1, "x": -1, "y": 0, "z": -8 },
		{ "id": 1, "x": 0, "y": 0, "z": -8 },
		{ "id": 1, "x": 1, "y": 0, "z": -8 },
		{ "id": 1, "x": 2, "y": 0, "z": -8 },
		{ "id": 1, "x": -2, "y": 0, "z": -9 },
		{ "id": 1, "x": -1, "y": 0, "z": -9 },
		{ "id": 1, "x": 0, "y": 0, "z": -9 },
		{ "id": 1, "x": 1, "y": 0, "z": -9 },
		{ "id": 1, "x": 2, "y": 0, "z": -9 },
		{ "id": 1, "x": -2, "y": 0, "z": -10 },
		{ "id": 1, "x": -1, "y": 0, "z": -10 },
		{ "id": 1, "x": 0, "y": 0, "z": -10 },
		{ "id": 1, "x": 1, "y": 0, "z": -10 },
		{ "id": 1, "x": 2, "y": 0, "z": -10 },
		{ "id": 1, "x": -2, "y": 0, "z": -11 },
		{ "id": 1, "x": -1, "y": 0, "z": -11 },
		{ "id": 1, "x": 0, "y": 0, "z": -11 },
		{ "id": 1, "x": 1, "y": 0, "z": -11 },
		{ "id": 1, "x": 2, "y": 0, "z": -11 },
		{ "id": 1, "x": -2, "y": 0, "z": -12 },
		{ "id": 1, "x": -1, "y": 0, "z": -12 },
		{ "id": 1, "x": 0, "y": 0, "z": -12 },
		{ "id": 1, "x": 1, "y": 0, "z": -12 },
		{ "id": 1, "x": 2, "y": 0, "z": -12 },

		{ "id": 1, "x": 0, "y": 1, "z": -11 },
		{ "id": 1, "x": 1, "y": 1, "z": -11 },
		{ "id": 1, "x": 2, "y": 1, "z": -11 },
		{ "id": 1, "x": 0, "y": 1, "z": -12 },
		{ "id": 1, "x": 1, "y": 1, "z": -12 },
		{ "id": 1, "x": 2, "y": 1, "z": -12 },

		{ "id": 1, "x": 5, "y": 2, "z": -9 },
		{ "id": 1, "x": 6, "y": 2, "z": -9 },
		{ "id": 1, "x": 7, "y": 2, "z": -9 },
		{ "id": 1, "x": 5, "y": 2, "z": -10 },
		{ "id": 1, "x": 6, "y": 2, "z": -10 },
		{ "id": 1, "x": 7, "y": 2, "z": -10 },
		{ "id": 1, "x": 5, "y": 2, "z": -11 },
		{ "id": 1, "x": 6, "y": 2, "z": -11 },
		{ "id": 1, "x": 7, "y": 2, "z": -11 },

		{ "id": 1, "x": 4, "y": 3, "z": -3 },
		{ "id": 1, "x": 5, "y": 3, "z": -3 },
		{ "id": 1, "x": 6, "y": 3, "z": -3 },
		{ "id": 1, "x": 4, "y": 3, "z": -4 },
		{ "id": 1, "x": 5, "y": 3, "z": -4 },
		{ "id": 1, "x": 6, "y": 3, "z": -4 },
		{ "id": 1, "x": 4, "y": 3, "z": -5 },
		{ "id": 1, "x": 5, "y": 3, "z": -5 },
		{ "id": 1, "x": 6, "y": 3, "z": -5 },

		{ "id": 1, "x": -3, "y": 3, "z": -2}
	]
}
