{
    "blocks": [
        {
            "id": 3,
            "x": 0,
            "y": 6,
            "z": 16
        },
        {
            "id": 3,
            "x": 0,
            "y": 1,
            "z": -17
        },
        {
            "id": 2,
            "x": 1,
            "y": 1,
            "z": -17
        },
        {
            "id": 2,
            "x": 3,
            "y": 2,
            "z": -21
        },
        {
            "id": 3,
            "x": 3,
            "y": 2,
            "z": -20
        },
        {
            "id": 2,
            "x": 3,
            "y": 2,
            "z": -19
        },
        {
            "id": 3,
            "x": 4,
            "y": 2,
            "z": -21
        },
        {
            "id": 3,
            "x": 4,
            "y": 2,
            "z": -20
        },
        {
            "id": 3,
            "x": 4,
            "y": 2,
            "z": -19
        },
        {
            "id": 2,
            "x": 5,
            "y": 2,
            "z": -21
        },
        {
            "id": 3,
            "x": 5,
            "y": 2,
            "z": -20
        },
        {
            "id": 2,
            "x": 5,
            "y": 2,
            "z": -19
        },
        {
            "id": 2,
            "x": 8,
            "y": 3,
            "z": -19
        },
        {
            "id": 3,
            "x": 8,
            "y": 3,
            "z": -18
        },
        {
            "id": 2,
            "x": 8,
            "y": 3,
            "z": -17
        },
        {
            "id": 3,
            "x": 9,
            "y": 3,
            "z": -19
        },
        {
            "id": 3,
            "x": 9,
            "y": 3,
            "z": -18
        },
        {
            "id": 3,
            "x": 9,
            "y": 3,
            "z": -17
        },
        {
            "id": 2,
            "x": 10,
            "y": 3,
            "z": -19
        },
        {
            "id": 3,
            "x": 10,
            "y": 3,
            "z": -18
        },
        {
            "id": 2,
            "x": 10,
            "y": 3,
            "z": -17
        },
        {
            "id": 2,
            "x": -6,
            "y": -4,
            "z": 0
        },
        {
            "id": 2,
            "x": -6,
            "y": -3,
            "z": 0
        },
        {
            "id": 2,
            "x": -6,
            "y": -3,
            "z": 2
        },
        {
            "id": 3,
            "x": -6,
            "y": -3,
            "z": 3
        },
        {
            "id": 2,
            "x": -6,
            "y": -3,
            "z": 4
        },
        {
            "id": 2,
            "x": -6,
            "y": -2,
            "z": 0
        },
        {
            "id": 3,
            "x": -5,
            "y": -4,
            "z": 0
        },
        {
            "id": 3,
            "x": -5,
            "y": -3,
            "z": 2
        },
        {
            "id": 3,
            "x": -5,
            "y": -3,
            "z": 3
        },
        {
            "id": 3,
            "x": -5,
            "y": -3,
            "z": 4
        },
        {
            "id": 2,
            "x": -5,
            "y": -2,
            "z": 6
        },
        {
            "id": 3,
            "x": -5,
            "y": -2,
            "z": 7
        },
        {
            "id": 2,
            "x": -5,
            "y": -2,
            "z": 8
        },
        {
            "id": 3,
            "x": -4,
            "y": -4,
            "z": 0
        },
        {
            "id": 2,
            "x": -4,
            "y": -3,
            "z": 2
        },
        {
            "id": 3,
            "x": -4,
            "y": -3,
            "z": 3
        },
        {
            "id": 2,
            "x": -4,
            "y": -3,
            "z": 4
        },
        {
            "id": 3,
            "x": -4,
            "y": -2,
            "z": 6
        },
        {
            "id": 3,
            "x": -4,
            "y": -2,
            "z": 7
        },
        {
            "id": 3,
            "x": -4,
            "y": -2,
            "z": 8
        },
        {
            "id": 3,
            "x": -3,
            "y": -4,
            "z": 0
        },
        {
            "id": 2,
            "x": -3,
            "y": -2,
            "z": 6
        },
        {
            "id": 3,
            "x": -3,
            "y": -2,
            "z": 7
        },
        {
            "id": 2,
            "x": -3,
            "y": -2,
            "z": 8
        },
        {
            "id": 3,
            "x": -2,
            "y": -4,
            "z": 0
        },
        {
            "id": 3,
            "x": -1,
            "y": -4,
            "z": 0
        },
        {
            "id": 2,
            "x": -1,
            "y": -1,
            "z": 7
        },
        {
            "id": 3,
            "x": -1,
            "y": -1,
            "z": 8
        },
        {
            "id": 2,
            "x": -1,
            "y": -1,
            "z": 9
        },
        {
            "id": 2,
            "x": -10,
            "y": 3,
            "z": -19
        },
        {
            "id": 3,
            "x": -10,
            "y": 3,
            "z": -18
        },
        {
            "id": 2,
            "x": -10,
            "y": 3,
            "z": -17
        },
        {
            "id": 3,
            "x": -9,
            "y": 3,
            "z": -19
        },
        {
            "id": 3,
            "x": -9,
            "y": 3,
            "z": -18
        },
        {
            "id": 3,
            "x": -9,
            "y": 3,
            "z": -17
        },
        {
            "id": 2,
            "x": -8,
            "y": 3,
            "z": -19
        },
        {
            "id": 3,
            "x": -8,
            "y": 3,
            "z": -18
        },
        {
            "id": 2,
            "x": -8,
            "y": 3,
            "z": -17
        },
        {
            "id": 2,
            "x": -5,
            "y": 2,
            "z": -21
        },
        {
            "id": 3,
            "x": -5,
            "y": 2,
            "z": -20
        },
        {
            "id": 2,
            "x": -5,
            "y": 2,
            "z": -19
        },
        {
            "id": 3,
            "x": -4,
            "y": 2,
            "z": -21
        },
        {
            "id": 3,
            "x": -4,
            "y": 2,
            "z": -20
        },
        {
            "id": 3,
            "x": -4,
            "y": 2,
            "z": -19
        },
        {
            "id": 2,
            "x": -3,
            "y": 2,
            "z": -21
        },
        {
            "id": 3,
            "x": -3,
            "y": 2,
            "z": -20
        },
        {
            "id": 2,
            "x": -3,
            "y": 2,
            "z": -19
        },
        {
            "id": 2,
            "x": -1,
            "y": 1,
            "z": -17
        },
        {
            "id": 3,
            "x": 0,
            "y": -4,
            "z": 0
        },
        {
            "id": 3,
            "x": 0,
            "y": -1,
            "z": 7
        },
        {
            "id": 3,
            "x": 0,
            "y": -1,
            "z": 8
        },
        {
            "id": 3,
            "x": 0,
            "y": -1,
            "z": 9
        },
        {
            "id": 3,
            "x": 1,
            "y": -4,
            "z": 0
        },
        {
            "id": 2,
            "x": 1,
            "y": -1,
            "z": 7
        },
        {
            "id": 3,
            "x": 1,
            "y": -1,
            "z": 8
        },
        {
            "id": 2,
            "x": 1,
            "y": -1,
            "z": 9
        },
        {
            "id": 3,
            "x": 2,
            "y": -4,
            "z": 0
        },
        {
            "id": 3,
            "x": 3,
            "y": -4,
            "z": 0
        },
        {
            "id": 2,
            "x": 3,
            "y": -2,
            "z": 6
        },
        {
            "id": 3,
            "x": 3,
            "y": -2,
            "z": 7
        },
        {
            "id": 2,
            "x": 3,
            "y": -2,
            "z": 8
        },
        {
            "id": 3,
            "x": 4,
            "y": -4,
            "z": 0
        },
        {
            "id": 2,
            "x": 4,
            "y": -3,
            "z": 2
        },
        {
            "id": 3,
            "x": 4,
            "y": -3,
            "z": 3
        },
        {
            "id": 2,
            "x": 4,
            "y": -3,
            "z": 4
        },
        {
            "id": 3,
            "x": 4,
            "y": -2,
            "z": 6
        },
        {
            "id": 3,
            "x": 4,
            "y": -2,
            "z": 7
        },
        {
            "id": 3,
            "x": 4,
            "y": -2,
            "z": 8
        },
        {
            "id": 3,
            "x": 5,
            "y": -4,
            "z": 0
        },
        {
            "id": 3,
            "x": 5,
            "y": -3,
            "z": 2
        },
        {
            "id": 3,
            "x": 5,
            "y": -3,
            "z": 3
        },
        {
            "id": 3,
            "x": 5,
            "y": -3,
            "z": 4
        },
        {
            "id": 2,
            "x": 5,
            "y": -2,
            "z": 6
        },
        {
            "id": 3,
            "x": 5,
            "y": -2,
            "z": 7
        },
        {
            "id": 2,
            "x": 5,
            "y": -2,
            "z": 8
        },
        {
            "id": 2,
            "x": 6,
            "y": -4,
            "z": 0
        },
        {
            "id": 2,
            "x": 6,
            "y": -3,
            "z": 0
        },
        {
            "id": 2,
            "x": 6,
            "y": -3,
            "z": 2
        },
        {
            "id": 3,
            "x": 6,
            "y": -3,
            "z": 3
        },
        {
            "id": 2,
            "x": 6,
            "y": -3,
            "z": 4
        },
        {
            "id": 2,
            "x": 6,
            "y": -2,
            "z": 0
        },
        {
            "id": 3,
            "x": 0,
            "y": -4,
            "z": -11
        },
        {
            "id": 3,
            "x": 0,
            "y": -4,
            "z": -10
        },
        {
            "id": 3,
            "x": 0,
            "y": -4,
            "z": -9
        },
        {
            "id": 3,
            "x": 0,
            "y": -4,
            "z": -8
        },
        {
            "id": 3,
            "x": 0,
            "y": -4,
            "z": -7
        },
        {
            "id": 3,
            "x": 0,
            "y": -4,
            "z": -6
        },
        {
            "id": 3,
            "x": 0,
            "y": -4,
            "z": -5
        },
        {
            "id": 3,
            "x": 0,
            "y": -4,
            "z": -4
        },
        {
            "id": 3,
            "x": 0,
            "y": -4,
            "z": -3
        },
        {
            "id": 3,
            "x": 0,
            "y": -4,
            "z": -2
        },
        {
            "id": 3,
            "x": 0,
            "y": -4,
            "z": -1
        },
        {
            "id": 3,
            "x": 1,
            "y": -4,
            "z": -11
        },
        {
            "id": 3,
            "x": 1,
            "y": -4,
            "z": -10
        },
        {
            "id": 3,
            "x": 1,
            "y": -4,
            "z": -9
        },
        {
            "id": 3,
            "x": 1,
            "y": -4,
            "z": -8
        },
        {
            "id": 3,
            "x": 1,
            "y": -4,
            "z": -7
        },
        {
            "id": 3,
            "x": 1,
            "y": -4,
            "z": -6
        },
        {
            "id": 3,
            "x": 1,
            "y": -4,
            "z": -5
        },
        {
            "id": 3,
            "x": 1,
            "y": -4,
            "z": -4
        },
        {
            "id": 3,
            "x": 1,
            "y": -4,
            "z": -3
        },
        {
            "id": 3,
            "x": 1,
            "y": -4,
            "z": -2
        },
        {
            "id": 3,
            "x": 1,
            "y": -4,
            "z": -1
        },
        {
            "id": 3,
            "x": 2,
            "y": -4,
            "z": -11
        },
        {
            "id": 3,
            "x": 2,
            "y": -4,
            "z": -10
        },
        {
            "id": 3,
            "x": 2,
            "y": -4,
            "z": -9
        },
        {
            "id": 3,
            "x": 2,
            "y": -4,
            "z": -8
        },
        {
            "id": 3,
            "x": 2,
            "y": -4,
            "z": -7
        },
        {
            "id": 3,
            "x": 2,
            "y": -4,
            "z": -6
        },
        {
            "id": 3,
            "x": 2,
            "y": -4,
            "z": -5
        },
        {
            "id": 3,
            "x": 2,
            "y": -4,
            "z": -4
        },
        {
            "id": 3,
            "x": 2,
            "y": -4,
            "z": -3
        },
        {
            "id": 3,
            "x": 2,
            "y": -4,
            "z": -2
        },
        {
            "id": 3,
            "x": 2,
            "y": -4,
            "z": -1
        },
        {
            "id": 2,
            "x": 2,
            "y": -3,
            "z": -8
        },
        {
            "id": 2,
            "x": 2,
            "y": -3,
            "z": -3
        },
        {
            "id": 2,
            "x": 2,
            "y": -2,
            "z": -8
        },
        {
            "id": 3,
            "x": 2,
            "y": -2,
            "z": -7
        },
        {
            "id": 3,
            "x": 2,
            "y": -2,
            "z": -6
        },
        {
            "id": 3,
            "x": 2,
            "y": -2,
            "z": -5
        },
        {
            "id": 3,
            "x": 2,
            "y": -2,
            "z": -4
        },
        {
            "id": 2,
            "x": 2,
            "y": -2,
            "z": -3
        },
        {
            "id": 2,
            "x": 2,
            "y": -1,
            "z": -8
        },
        {
            "id": 2,
            "x": 2,
            "y": -1,
            "z": -3
        },
        {
            "id": 3,
            "x": 3,
            "y": -4,
            "z": -11
        },
        {
            "id": 3,
            "x": 3,
            "y": -4,
            "z": -10
        },
        {
            "id": 3,
            "x": 3,
            "y": -4,
            "z": -9
        },
        {
            "id": 3,
            "x": 3,
            "y": -4,
            "z": -8
        },
        {
            "id": 3,
            "x": 3,
            "y": -4,
            "z": -7
        },
        {
            "id": 3,
            "x": 3,
            "y": -4,
            "z": -6
        },
        {
            "id": 3,
            "x": 3,
            "y": -4,
            "z": -5
        },
        {
            "id": 3,
            "x": 3,
            "y": -4,
            "z": -4
        },
        {
            "id": 3,
            "x": 3,
            "y": -4,
            "z": -3
        },
        {
            "id": 3,
            "x": 3,
            "y": -4,
            "z": -2
        },
        {
            "id": 3,
            "x": 3,
            "y": -4,
            "z": -1
        },
        {
            "id": 3,
            "x": 4,
            "y": -4,
            "z": -11
        },
        {
            "id": 3,
            "x": 4,
            "y": -4,
            "z": -10
        },
        {
            "id": 3,
            "x": 4,
            "y": -4,
            "z": -9
        },
        {
            "id": 3,
            "x": 4,
            "y": -4,
            "z": -8
        },
        {
            "id": 3,
            "x": 4,
            "y": -4,
            "z": -7
        },
        {
            "id": 3,
            "x": 4,
            "y": -4,
            "z": -6
        },
        {
            "id": 3,
            "x": 4,
            "y": -4,
            "z": -5
        },
        {
            "id": 3,
            "x": 4,
            "y": -4,
            "z": -4
        },
        {
            "id": 3,
            "x": 4,
            "y": -4,
            "z": -3
        },
        {
            "id": 3,
            "x": 4,
            "y": -4,
            "z": -2
        },
        {
            "id": 3,
            "x": 4,
            "y": -4,
            "z": -1
        },
        {
            "id": 3,
            "x": 5,
            "y": -4,
            "z": -11
        },
        {
            "id": 3,
            "x": 5,
            "y": -4,
            "z": -10
        },
        {
            "id": 3,
            "x": 5,
            "y": -4,
            "z": -9
        },
        {
            "id": 3,
            "x": 5,
            "y": -4,
            "z": -8
        },
        {
            "id": 3,
            "x": 5,
            "y": -4,
            "z": -7
        },
        {
            "id": 3,
            "x": 5,
            "y": -4,
            "z": -6
        },
        {
            "id": 3,
            "x": 5,
            "y": -4,
            "z": -5
        },
        {
            "id": 3,
            "x": 5,
            "y": -4,
            "z": -4
        },
        {
            "id": 3,
            "x": 5,
            "y": -4,
            "z": -3
        },
        {
            "id": 3,
            "x": 5,
            "y": -4,
            "z": -2
        },
        {
            "id": 3,
            "x": 5,
            "y": -4,
            "z": -1
        },
        {
            "id": 2,
            "x": 6,
            "y": -4,
            "z": -11
        },
        {
            "id": 3,
            "x": 6,
            "y": -4,
            "z": -10
        },
        {
            "id": 3,
            "x": 6,
            "y": -4,
            "z": -9
        },
        {
            "id": 3,
            "x": 6,
            "y": -4,
            "z": -8
        },
        {
            "id": 3,
            "x": 6,
            "y": -4,
            "z": -7
        },
        {
            "id": 3,
            "x": 6,
            "y": -4,
            "z": -6
        },
        {
            "id": 3,
            "x": 6,
            "y": -4,
            "z": -5
        },
        {
            "id": 3,
            "x": 6,
            "y": -4,
            "z": -4
        },
        {
            "id": 3,
            "x": 6,
            "y": -4,
            "z": -3
        },
        {
            "id": 3,
            "x": 6,
            "y": -4,
            "z": -2
        },
        {
            "id": 3,
            "x": 6,
            "y": -4,
            "z": -1
        },
        {
            "id": 2,
            "x": 6,
            "y": -3,
            "z": -11
        },
        {
            "id": 2,
            "x": 6,
            "y": -2,
            "z": -11
        },
        {
            "id": 3,
            "x": 0,
            "y": 0,
            "z": -12
        },
        {
            "id": 3,
            "x": 0,
            "y": 0,
            "z": -11
        },
        {
            "id": 3,
            "x": 0,
            "y": 0,
            "z": -10
        },
        {
            "id": 3,
            "x": 0,
            "y": 0,
            "z": -9
        },
        {
            "id": 3,
            "x": 0,
            "y": 0,
            "z": -8
        },
        {
            "id": 3,
            "x": 0,
            "y": 0,
            "z": -3
        },
        {
            "id": 3,
            "x": 0,
            "y": 0,
            "z": -2
        },
        {
            "id": 3,
            "x": 0,
            "y": 0,
            "z": -1
        },
        {
            "id": 3,
            "x": 0,
            "y": 1,
            "z": -16
        },
        {
            "id": 3,
            "x": 0,
            "y": 1,
            "z": -15
        },
        {
            "id": 3,
            "x": 1,
            "y": 0,
            "z": -12
        },
        {
            "id": 3,
            "x": 1,
            "y": 0,
            "z": -11
        },
        {
            "id": 3,
            "x": 1,
            "y": 0,
            "z": -10
        },
        {
            "id": 3,
            "x": 1,
            "y": 0,
            "z": -9
        },
        {
            "id": 3,
            "x": 1,
            "y": 0,
            "z": -8
        },
        {
            "id": 3,
            "x": 1,
            "y": 0,
            "z": -3
        },
        {
            "id": 3,
            "x": 1,
            "y": 0,
            "z": -2
        },
        {
            "id": 3,
            "x": 1,
            "y": 0,
            "z": -1
        },
        {
            "id": 3,
            "x": 1,
            "y": 1,
            "z": -16
        },
        {
            "id": 2,
            "x": 1,
            "y": 1,
            "z": -15
        },
        {
            "id": 2,
            "x": 2,
            "y": 0,
            "z": -12
        },
        {
            "id": 3,
            "x": 2,
            "y": 0,
            "z": -11
        },
        {
            "id": 3,
            "x": 2,
            "y": 0,
            "z": -10
        },
        {
            "id": 3,
            "x": 2,
            "y": 0,
            "z": -9
        },
        {
            "id": 2,
            "x": 2,
            "y": 0,
            "z": -8
        },
        {
            "id": 2,
            "x": 2,
            "y": 0,
            "z": -3
        },
        {
            "id": 3,
            "x": 2,
            "y": 0,
            "z": -2
        },
        {
            "id": 3,
            "x": 2,
            "y": 0,
            "z": -1
        },
        {
            "id": 2,
            "x": 2,
            "y": 1,
            "z": -12
        },
        {
            "id": 2,
            "x": 2,
            "y": 1,
            "z": -8
        },
        {
            "id": 2,
            "x": 2,
            "y": 1,
            "z": -3
        },
        {
            "id": 2,
            "x": 10,
            "y": 4,
            "z": -2
        },
        {
            "id": 3,
            "x": 10,
            "y": 4,
            "z": -1
        },
        {
            "id": 3,
            "x": 11,
            "y": 4,
            "z": -2
        },
        {
            "id": 3,
            "x": 11,
            "y": 4,
            "z": -1
        },
        {
            "id": 2,
            "x": 12,
            "y": 3,
            "z": -7
        },
        {
            "id": 3,
            "x": 12,
            "y": 3,
            "z": -6
        },
        {
            "id": 2,
            "x": 12,
            "y": 3,
            "z": -5
        },
        {
            "id": 2,
            "x": 12,
            "y": 4,
            "z": -14
        },
        {
            "id": 3,
            "x": 12,
            "y": 4,
            "z": -13
        },
        {
            "id": 2,
            "x": 12,
            "y": 4,
            "z": -12
        },
        {
            "id": 2,
            "x": 12,
            "y": 4,
            "z": -2
        },
        {
            "id": 3,
            "x": 12,
            "y": 4,
            "z": -1
        },
        {
            "id": 3,
            "x": 13,
            "y": 3,
            "z": -7
        },
        {
            "id": 3,
            "x": 13,
            "y": 3,
            "z": -6
        },
        {
            "id": 3,
            "x": 13,
            "y": 3,
            "z": -5
        },
        {
            "id": 3,
            "x": 13,
            "y": 4,
            "z": -14
        },
        {
            "id": 3,
            "x": 13,
            "y": 4,
            "z": -13
        },
        {
            "id": 3,
            "x": 13,
            "y": 4,
            "z": -12
        },
        {
            "id": 2,
            "x": 14,
            "y": 3,
            "z": -7
        },
        {
            "id": 3,
            "x": 14,
            "y": 3,
            "z": -6
        },
        {
            "id": 2,
            "x": 14,
            "y": 3,
            "z": -5
        },
        {
            "id": 2,
            "x": 14,
            "y": 4,
            "z": -14
        },
        {
            "id": 3,
            "x": 14,
            "y": 4,
            "z": -13
        },
        {
            "id": 2,
            "x": 14,
            "y": 4,
            "z": -12
        },
        {
            "id": 2,
            "x": -14,
            "y": 3,
            "z": -7
        },
        {
            "id": 3,
            "x": -14,
            "y": 3,
            "z": -6
        },
        {
            "id": 2,
            "x": -14,
            "y": 3,
            "z": -5
        },
        {
            "id": 2,
            "x": -14,
            "y": 4,
            "z": -14
        },
        {
            "id": 3,
            "x": -14,
            "y": 4,
            "z": -13
        },
        {
            "id": 2,
            "x": -14,
            "y": 4,
            "z": -12
        },
        {
            "id": 3,
            "x": -13,
            "y": 3,
            "z": -7
        },
        {
            "id": 3,
            "x": -13,
            "y": 3,
            "z": -6
        },
        {
            "id": 3,
            "x": -13,
            "y": 3,
            "z": -5
        },
        {
            "id": 3,
            "x": -13,
            "y": 4,
            "z": -14
        },
        {
            "id": 3,
            "x": -13,
            "y": 4,
            "z": -13
        },
        {
            "id": 3,
            "x": -13,
            "y": 4,
            "z": -12
        },
        {
            "id": 2,
            "x": -12,
            "y": 3,
            "z": -7
        },
        {
            "id": 3,
            "x": -12,
            "y": 3,
            "z": -6
        },
        {
            "id": 2,
            "x": -12,
            "y": 3,
            "z": -5
        },
        {
            "id": 2,
            "x": -12,
            "y": 4,
            "z": -14
        },
        {
            "id": 3,
            "x": -12,
            "y": 4,
            "z": -13
        },
        {
            "id": 2,
            "x": -12,
            "y": 4,
            "z": -12
        },
        {
            "id": 2,
            "x": -12,
            "y": 4,
            "z": -2
        },
        {
            "id": 3,
            "x": -12,
            "y": 4,
            "z": -1
        },
        {
            "id": 3,
            "x": -11,
            "y": 4,
            "z": -2
        },
        {
            "id": 3,
            "x": -11,
            "y": 4,
            "z": -1
        },
        {
            "id": 2,
            "x": -10,
            "y": 4,
            "z": -2
        },
        {
            "id": 3,
            "x": -10,
            "y": 4,
            "z": -1
        },
        {
            "id": 2,
            "x": -2,
            "y": 0,
            "z": -12
        },
        {
            "id": 3,
            "x": -2,
            "y": 0,
            "z": -11
        },
        {
            "id": 3,
            "x": -2,
            "y": 0,
            "z": -10
        },
        {
            "id": 3,
            "x": -2,
            "y": 0,
            "z": -9
        },
        {
            "id": 2,
            "x": -2,
            "y": 0,
            "z": -8
        },
        {
            "id": 2,
            "x": -2,
            "y": 0,
            "z": -3
        },
        {
            "id": 3,
            "x": -2,
            "y": 0,
            "z": -2
        },
        {
            "id": 3,
            "x": -2,
            "y": 0,
            "z": -1
        },
        {
            "id": 2,
            "x": -2,
            "y": 1,
            "z": -12
        },
        {
            "id": 2,
            "x": -2,
            "y": 1,
            "z": -8
        },
        {
            "id": 2,
            "x": -2,
            "y": 1,
            "z": -3
        },
        {
            "id": 3,
            "x": -1,
            "y": 0,
            "z": -12
        },
        {
            "id": 3,
            "x": -1,
            "y": 0,
            "z": -11
        },
        {
            "id": 3,
            "x": -1,
            "y": 0,
            "z": -10
        },
        {
            "id": 3,
            "x": -1,
            "y": 0,
            "z": -9
        },
        {
            "id": 3,
            "x": -1,
            "y": 0,
            "z": -8
        },
        {
            "id": 3,
            "x": -1,
            "y": 0,
            "z": -3
        },
        {
            "id": 3,
            "x": -1,
            "y": 0,
            "z": -2
        },
        {
            "id": 3,
            "x": -1,
            "y": 0,
            "z": -1
        },
        {
            "id": 3,
            "x": -1,
            "y": 1,
            "z": -16
        },
        {
            "id": 2,
            "x": -1,
            "y": 1,
            "z": -15
        },
        {
            "id": 2,
            "x": -6,
            "y": -4,
            "z": -11
        },
        {
            "id": 3,
            "x": -6,
            "y": -4,
            "z": -10
        },
        {
            "id": 3,
            "x": -6,
            "y": -4,
            "z": -9
        },
        {
            "id": 3,
            "x": -6,
            "y": -4,
            "z": -8
        },
        {
            "id": 3,
            "x": -6,
            "y": -4,
            "z": -7
        },
        {
            "id": 3,
            "x": -6,
            "y": -4,
            "z": -6
        },
        {
            "id": 3,
            "x": -6,
            "y": -4,
            "z": -5
        },
        {
            "id": 3,
            "x": -6,
            "y": -4,
            "z": -4
        },
        {
            "id": 3,
            "x": -6,
            "y": -4,
            "z": -3
        },
        {
            "id": 3,
            "x": -6,
            "y": -4,
            "z": -2
        },
        {
            "id": 3,
            "x": -6,
            "y": -4,
            "z": -1
        },
        {
            "id": 2,
            "x": -6,
            "y": -3,
            "z": -11
        },
        {
            "id": 2,
            "x": -6,
            "y": -2,
            "z": -11
        },
        {
            "id": 3,
            "x": -5,
            "y": -4,
            "z": -11
        },
        {
            "id": 3,
            "x": -5,
            "y": -4,
            "z": -10
        },
        {
            "id": 3,
            "x": -5,
            "y": -4,
            "z": -9
        },
        {
            "id": 3,
            "x": -5,
            "y": -4,
            "z": -8
        },
        {
            "id": 3,
            "x": -5,
            "y": -4,
            "z": -7
        },
        {
            "id": 3,
            "x": -5,
            "y": -4,
            "z": -6
        },
        {
            "id": 3,
            "x": -5,
            "y": -4,
            "z": -5
        },
        {
            "id": 3,
            "x": -5,
            "y": -4,
            "z": -4
        },
        {
            "id": 3,
            "x": -5,
            "y": -4,
            "z": -3
        },
        {
            "id": 3,
            "x": -5,
            "y": -4,
            "z": -2
        },
        {
            "id": 3,
            "x": -5,
            "y": -4,
            "z": -1
        },
        {
            "id": 3,
            "x": -4,
            "y": -4,
            "z": -11
        },
        {
            "id": 3,
            "x": -4,
            "y": -4,
            "z": -10
        },
        {
            "id": 3,
            "x": -4,
            "y": -4,
            "z": -9
        },
        {
            "id": 3,
            "x": -4,
            "y": -4,
            "z": -8
        },
        {
            "id": 3,
            "x": -4,
            "y": -4,
            "z": -7
        },
        {
            "id": 3,
            "x": -4,
            "y": -4,
            "z": -6
        },
        {
            "id": 3,
            "x": -4,
            "y": -4,
            "z": -5
        },
        {
            "id": 3,
            "x": -4,
            "y": -4,
            "z": -4
        },
        {
            "id": 3,
            "x": -4,
            "y": -4,
            "z": -3
        },
        {
            "id": 3,
            "x": -4,
            "y": -4,
            "z": -2
        },
        {
            "id": 3,
            "x": -4,
            "y": -4,
            "z": -1
        },
        {
            "id": 3,
            "x": -3,
            "y": -4,
            "z": -11
        },
        {
            "id": 3,
            "x": -3,
            "y": -4,
            "z": -10
        },
        {
            "id": 3,
            "x": -3,
            "y": -4,
            "z": -9
        },
        {
            "id": 3,
            "x": -3,
            "y": -4,
            "z": -8
        },
        {
            "id": 3,
            "x": -3,
            "y": -4,
            "z": -7
        },
        {
            "id": 3,
            "x": -3,
            "y": -4,
            "z": -6
        },
        {
            "id": 3,
            "x": -3,
            "y": -4,
            "z": -5
        },
        {
            "id": 3,
            "x": -3,
            "y": -4,
            "z": -4
        },
        {
            "id": 3,
            "x": -3,
            "y": -4,
            "z": -3
        },
        {
            "id": 3,
            "x": -3,
            "y": -4,
            "z": -2
        },
        {
            "id": 3,
            "x": -3,
            "y": -4,
            "z": -1
        },
        {
            "id": 3,
            "x": -2,
            "y": -4,
            "z": -11
        },
        {
            "id": 3,
            "x": -2,
            "y": -4,
            "z": -10
        },
        {
            "id": 3,
            "x": -2,
            "y": -4,
            "z": -9
        },
        {
            "id": 3,
            "x": -2,
            "y": -4,
            "z": -8
        },
        {
            "id": 3,
            "x": -2,
            "y": -4,
            "z": -7
        },
        {
            "id": 3,
            "x": -2,
            "y": -4,
            "z": -6
        },
        {
            "id": 3,
            "x": -2,
            "y": -4,
            "z": -5
        },
        {
            "id": 3,
            "x": -2,
            "y": -4,
            "z": -4
        },
        {
            "id": 3,
            "x": -2,
            "y": -4,
            "z": -3
        },
        {
            "id": 3,
            "x": -2,
            "y": -4,
            "z": -2
        },
        {
            "id": 3,
            "x": -2,
            "y": -4,
            "z": -1
        },
        {
            "id": 2,
            "x": -2,
            "y": -3,
            "z": -8
        },
        {
            "id": 2,
            "x": -2,
            "y": -3,
            "z": -3
        },
        {
            "id": 2,
            "x": -2,
            "y": -2,
            "z": -8
        },
        {
            "id": 3,
            "x": -2,
            "y": -2,
            "z": -7
        },
        {
            "id": 3,
            "x": -2,
            "y": -2,
            "z": -6
        },
        {
            "id": 3,
            "x": -2,
            "y": -2,
            "z": -5
        },
        {
            "id": 3,
            "x": -2,
            "y": -2,
            "z": -4
        },
        {
            "id": 2,
            "x": -2,
            "y": -2,
            "z": -3
        },
        {
            "id": 2,
            "x": -2,
            "y": -1,
            "z": -8
        },
        {
            "id": 2,
            "x": -2,
            "y": -1,
            "z": -3
        },
        {
            "id": 3,
            "x": -1,
            "y": -4,
            "z": -11
        },
        {
            "id": 3,
            "x": -1,
            "y": -4,
            "z": -10
        },
        {
            "id": 3,
            "x": -1,
            "y": -4,
            "z": -9
        },
        {
            "id": 3,
            "x": -1,
            "y": -4,
            "z": -8
        },
        {
            "id": 3,
            "x": -1,
            "y": -4,
            "z": -7
        },
        {
            "id": 3,
            "x": -1,
            "y": -4,
            "z": -6
        },
        {
            "id": 3,
            "x": -1,
            "y": -4,
            "z": -5
        },
        {
            "id": 3,
            "x": -1,
            "y": -4,
            "z": -4
        },
        {
            "id": 3,
            "x": -1,
            "y": -4,
            "z": -3
        },
        {
            "id": 3,
            "x": -1,
            "y": -4,
            "z": -2
        },
        {
            "id": 3,
            "x": -1,
            "y": -4,
            "z": -1
        },
        {
            "id": 3,
            "x": 0,
            "y": 0,
            "z": 0
        },
        {
            "id": 3,
            "x": 0,
            "y": 0,
            "z": 1
        },
        {
            "id": 3,
            "x": 0,
            "y": 0,
            "z": 3
        },
        {
            "id": 3,
            "x": 0,
            "y": 0,
            "z": 4
        },
        {
            "id": 3,
            "x": 0,
            "y": 0,
            "z": 5
        },
        {
            "id": 3,
            "x": 0,
            "y": 6,
            "z": 4
        },
        {
            "id": 3,
            "x": 0,
            "y": 6,
            "z": 5
        },
        {
            "id": 3,
            "x": 0,
            "y": 6,
            "z": 6
        },
        {
            "id": 3,
            "x": 0,
            "y": 6,
            "z": 7
        },
        {
            "id": 3,
            "x": 0,
            "y": 6,
            "z": 8
        },
        {
            "id": 3,
            "x": 0,
            "y": 6,
            "z": 9
        },
        {
            "id": 3,
            "x": 1,
            "y": 0,
            "z": 0
        },
        {
            "id": 3,
            "x": 1,
            "y": 0,
            "z": 1
        },
        {
            "id": 2,
            "x": 1,
            "y": 0,
            "z": 3
        },
        {
            "id": 3,
            "x": 1,
            "y": 0,
            "z": 4
        },
        {
            "id": 2,
            "x": 1,
            "y": 0,
            "z": 5
        },
        {
            "id": 2,
            "x": 1,
            "y": 6,
            "z": 4
        },
        {
            "id": 3,
            "x": 1,
            "y": 6,
            "z": 5
        },
        {
            "id": 3,
            "x": 1,
            "y": 6,
            "z": 6
        },
        {
            "id": 3,
            "x": 1,
            "y": 6,
            "z": 7
        },
        {
            "id": 3,
            "x": 1,
            "y": 6,
            "z": 8
        },
        {
            "id": 2,
            "x": 1,
            "y": 6,
            "z": 9
        },
        {
            "id": 3,
            "x": 2,
            "y": 0,
            "z": 0
        },
        {
            "id": 2,
            "x": 2,
            "y": 0,
            "z": 1
        },
        {
            "id": 2,
            "x": 2,
            "y": 1,
            "z": 1
        },
        {
            "id": 2,
            "x": 3,
            "y": 5,
            "z": 2
        },
        {
            "id": 3,
            "x": 3,
            "y": 5,
            "z": 3
        },
        {
            "id": 2,
            "x": 3,
            "y": 5,
            "z": 4
        },
        {
            "id": 3,
            "x": 4,
            "y": 5,
            "z": 2
        },
        {
            "id": 3,
            "x": 4,
            "y": 5,
            "z": 3
        },
        {
            "id": 3,
            "x": 4,
            "y": 5,
            "z": 4
        },
        {
            "id": 2,
            "x": 5,
            "y": 5,
            "z": 1
        },
        {
            "id": 3,
            "x": 5,
            "y": 5,
            "z": 2
        },
        {
            "id": 3,
            "x": 5,
            "y": 5,
            "z": 3
        },
        {
            "id": 2,
            "x": 5,
            "y": 5,
            "z": 4
        },
        {
            "id": 3,
            "x": 6,
            "y": 5,
            "z": 1
        },
        {
            "id": 3,
            "x": 6,
            "y": 5,
            "z": 2
        },
        {
            "id": 3,
            "x": 6,
            "y": 5,
            "z": 3
        },
        {
            "id": 2,
            "x": 7,
            "y": 5,
            "z": 1
        },
        {
            "id": 3,
            "x": 7,
            "y": 5,
            "z": 2
        },
        {
            "id": 2,
            "x": 7,
            "y": 5,
            "z": 3
        },
        {
            "id": 2,
            "x": 10,
            "y": 4,
            "z": 0
        },
        {
            "id": 3,
            "x": 11,
            "y": 4,
            "z": 0
        },
        {
            "id": 2,
            "x": 12,
            "y": 4,
            "z": 0
        },
        {
            "id": 2,
            "x": -12,
            "y": 4,
            "z": 0
        },
        {
            "id": 3,
            "x": -11,
            "y": 4,
            "z": 0
        },
        {
            "id": 2,
            "x": -10,
            "y": 4,
            "z": 0
        },
        {
            "id": 2,
            "x": -7,
            "y": 5,
            "z": 1
        },
        {
            "id": 3,
            "x": -7,
            "y": 5,
            "z": 2
        },
        {
            "id": 2,
            "x": -7,
            "y": 5,
            "z": 3
        },
        {
            "id": 3,
            "x": -6,
            "y": 5,
            "z": 1
        },
        {
            "id": 3,
            "x": -6,
            "y": 5,
            "z": 2
        },
        {
            "id": 3,
            "x": -6,
            "y": 5,
            "z": 3
        },
        {
            "id": 2,
            "x": -5,
            "y": 5,
            "z": 1
        },
        {
            "id": 3,
            "x": -5,
            "y": 5,
            "z": 2
        },
        {
            "id": 3,
            "x": -5,
            "y": 5,
            "z": 3
        },
        {
            "id": 2,
            "x": -5,
            "y": 5,
            "z": 4
        },
        {
            "id": 3,
            "x": -4,
            "y": 5,
            "z": 2
        },
        {
            "id": 3,
            "x": -4,
            "y": 5,
            "z": 3
        },
        {
            "id": 3,
            "x": -4,
            "y": 5,
            "z": 4
        },
        {
            "id": 2,
            "x": -3,
            "y": 5,
            "z": 2
        },
        {
            "id": 3,
            "x": -3,
            "y": 5,
            "z": 3
        },
        {
            "id": 2,
            "x": -3,
            "y": 5,
            "z": 4
        },
        {
            "id": 3,
            "x": -2,
            "y": 0,
            "z": 0
        },
        {
            "id": 2,
            "x": -2,
            "y": 0,
            "z": 1
        },
        {
            "id": 2,
            "x": -2,
            "y": 1,
            "z": 1
        },
        {
            "id": 3,
            "x": -1,
            "y": 0,
            "z": 0
        },
        {
            "id": 3,
            "x": -1,
            "y": 0,
            "z": 1
        },
        {
            "id": 2,
            "x": -1,
            "y": 0,
            "z": 3
        },
        {
            "id": 3,
            "x": -1,
            "y": 0,
            "z": 4
        },
        {
            "id": 2,
            "x": -1,
            "y": 0,
            "z": 5
        },
        {
            "id": 2,
            "x": -1,
            "y": 6,
            "z": 4
        },
        {
            "id": 3,
            "x": -1,
            "y": 6,
            "z": 5
        },
        {
            "id": 3,
            "x": -1,
            "y": 6,
            "z": 6
        },
        {
            "id": 3,
            "x": -1,
            "y": 6,
            "z": 7
        },
        {
            "id": 3,
            "x": -1,
            "y": 6,
            "z": 8
        },
        {
            "id": 2,
            "x": -1,
            "y": 6,
            "z": 9
        }
    ]
}
